Workbook

Sheet Données brutes
A1: id_questionnaire | B1: pages_source | C1: etablissement | D1: ville | E1: departement | F1: type_etablissement | G1: sexe | H1: age | I1: anciennete | J1: statut | K1: statut_autre | L1: diplome_pro | M1: diplome_academique | N1: discipline | O1: discipline_autre | P1: formation_12mois | Q1: nb_jours_formation | R1: formation_distance | S1: satisfaction_distance | T1: equipements__smartphone | U1: equipements__ordinateur_tablette | V1: equipements__connexion_internet_a_domicil | W1: equipements__aucun_de_ces_equipements | X1: equipements | Y1: ame_a | Z1: ame_b | AA1: ame_c | AB1: q1 | AC1: q2 | AD1: q3 | AE1: q4 | AF1: q5 | AG1: q6 | AH1: q7__ministere | AI1: q7__inspection | AJ1: q7__etablissement | AK1: q7__ong_partenaires | AL1: q7__initiative_personnelle | AM1: q7__autre | AN1: q7 | AO1: q8 | AP1: q9 | AQ1: q10 | AR1: q11 | AS1: q12 | AT1: q13 | AU1: q14 | AV1: q15__visite_de_classe_en_situatio | AW1: q15__entretien_individuel_avec_un | AX1: q15__mentorat_tutorat_par_un_pair | AY1: q15__reunion_collective_de_suivi_ | AZ1: q15__aucun_accompagnement_recu | BA1: q15 | BB1: q16 | BC1: q17 | BD1: q18 | BE1: q19 | BF1: q20 | BG1: q21 | BH1: q22 | BI1: q23 | BJ1: q24 | BK1: q25 | BL1: q26 | BM1: q27 | BN1: q28 | BO1: q29 | BP1: q30 | BQ1: q31 | BR1: q32 | BS1: q33 | BT1: q34 | BU1: q35 | BV1: q36 | BW1: q37 | BX1: q38 | BY1: q39 | BZ1: q40 | CA1: q41 | CB1: q42__acces_limite_a_internet | CC1: q42__materiel_insuffisant | CD1: q42__manque_de_competences_numeri | CE1: q42__pas_d_obstacle_majeur | CF1: q42 | CG1: q43 | CH1: q44 | CI1: q45 | CJ1: q46 | CK1: q47 | CL1: q48 | CM1: q49 | CN1: q50a | CO1: q50b | CP1: q50c | CQ1: q50d | CR1: a_verifier | CS1: verifie | CT1: remarques
A2: 1 | B2: 1-2-3-4 | C2: CEG 1 Porto-Novo | D2: Cotonou | E2: ZOU | F2: Public | G2: Masculin | H2: moins de 30 ans | I2: 11-20 ans | J2: FE | M2: Maîtrise | N2: Sciences et Technologies | P2: Non | Q2: 1 à 2 jours | R2: Non | S2: 3 | T2: 0 | U2: 1 | V2: 0 | W2: 1 | X2: Aucun de ces équipements | Ordinateur/tablette | AB2: 4 | AC2: 5 | AD2: 4 | AE2: 4 | AF2: 3 | AG2: 2 | AH2: 0 | AI2: 0 | AJ2: 1 | AK2: 0 | AL2: 0 | AM2: 0 | AN2: Établissement | AO2: 1 | AP2: 5 | AQ2: 3 | AR2: 4 | AS2: 4 | AT2: 4 | AU2: 2 | AV2: 0 | AW2: 0 | AX2: 0 | AY2: 1 | AZ2: 0 | BA2: Réunion collective de suivi (conseil d'enseignement, animation pédagogique) | BB2: Jamais | BC2: 3 | BD2: 2 | BE2: 2 | BF2: 4 | BG2: 5 | BH2: 4 | BI2: 2 | BJ2: 3 | BK2: 5 | BL2: 3 | BM2: 4 | BN2: 4 | BO2: 5 | BP2: 3 | BQ2: 4 | BR2: 4 | BS2: 3 | BT2: 3 | BU2: 3 | BV2: 5 | BW2: 4 | BX2: 3 | BY2: 2 | BZ2: 4 | CA2: Parfois | CB2: 0 | CC2: 1 | CD2: 0 | CE2: 0 | CF2: Matériel insuffisant | CG2: 3 | CH2: 2 | CI2: 3 | CJ2: 5 | CK2: À distance (en ligne) | CL2: Modules répartis sur plusieurs semaines | CM2: Oui, absolument | CN2: Motiver les enseignants et former les encadreurs. | CP2: Motiver les enseignants et former les encadreurs. | CQ2: Manque de moyens et de suivi de proximité.
A3: 2 | B3: 5-6-7-8 | C3: CEG 7 Lokossa | D3: Cotonou | E3: ATACORA | G3: Masculin | H3: 50 ans et plus | I3: plus de 20 ans | J3: AME | L3: CAPES | M3: Licence | N3: Sciences et Technologies | P3: Non | Q3: 6 à 10 jours | R3: Non | S3: 2 | T3: 0 | U3: 1 | V3: 0 | W3: 1 | X3: Aucun de ces équipements | Ordinateur/tablette | Y3: 1 | Z3: 5 | AA3: 4 | AB3: 5 | AC3: 2 | AD3: 1 | AE3: 4 | AF3: 3 | AG3: 3 | AH3: 0 | AI3: 0 | AJ3: 0 | AK3: 1 | AL3: 0 | AM3: 1 | AN3: ONG/Partenaires | Autre | AO3: 4 | AP3: 5 | AQ3: 3 | AR3: 4 | AS3: 3 | AT3: 2 | AU3: 2 | AV3: 0 | AW3: 0 | AX3: 0 | AY3: 1 | AZ3: 1 | BA3: Aucun accompagnement reçu | Réunion collective de suivi (conseil d'enseignement, animation pédagogique) | BB3: 1 à 2 fois | BC3: 3 | BD3: 3 | BE3: 1 | BF3: 4 | BG3: 4 | BH3: 4 | BI3: 5 | BJ3: 2 | BK3: 4 | BL3: 2 | BM3: 5 | BN3: 2 | BO3: 3 | BP3: 3 | BR3: 2 | BS3: 4 | BT3: 4 | BU3: 5 | BV3: 1 | BW3: 3 | BX3: 4 | BZ3: 3 | CA3: Très souvent | CB3: 0 | CC3: 0 | CD3: 1 | CE3: 0 | CF3: Manque de compétences numériques | CG3: 4 | CH3: 3 | CI3: 3 | CJ3: 3 | CK3: Présentiel pur | CL3: Formation longue (plusieurs semaines continues) | CM3: Non, pas nécessaire | CO3: Manque de moyens et de suivi de proximité. | CP3: Manque de moyens et de suivi de proximité. | CR3: oui
A4: 3 | B4: 9-10-11-12 | C4: CEG 2 Natitingou | D4: Cotonou | E4: LITTORAL | F4: Public | G4: Masculin | H4: 50 ans et plus | I4: moins de 5 ans | J4: ACDPE | L4: Master Pro | N4: Sciences et Technologies | Q4: 3 à 5 jours | R4: Oui | S4: 3 | T4: 1 | U4: 0 | V4: 0 | W4: 1 | X4: Smartphone | Aucun de ces équipements | AB4: 3 | AC4: 1 | AD4: 2 | AE4: 4 | AF4: 5 | AG4: 4 | AH4: 1 | AI4: 0 | AJ4: 0 | AK4: 0 | AL4: 0 | AM4: 0 | AN4: Ministère | AO4: 5 | AP4: 3 | AQ4: 5 | AR4: 4 | AS4: 5 | AT4: 3 | AU4: 3 | AV4: 1 | AW4: 0 | AX4: 0 | AY4: 0 | AZ4: 1 | BA4: Visite de classe en situation | Aucun accompagnement reçu | BC4: 1 | BD4: 4 | BE4: 5 | BF4: 2 | BG4: 5 | BH4: 4 | BI4: 2 | BJ4: 1 | BK4: 3 | BL4: 3 | BM4: 5 | BN4: 2 | BO4: 3 | BP4: 4 | BQ4: 5 | BR4: 3 | BS4: 2 | BT4: 3 | BU4: 4 | BV4: 4 | BW4: 5 | BX4: 4 | BY4: 5 | BZ4: 5 | CA4: Très souvent | CB4: 0 | CC4: 1 | CD4: 1 | CE4: 0 | CF4: Matériel insuffisant | Manque de compétences numériques | CG4: 3 | CH4: 4 | CI4: 4 | CJ4: 2 | CK4: Présentiel pur | CL4: Une journée complète | CM4: Non, pas nécessaire | CN4: Motiver les enseignants et former les encadreurs. | CO4: Manque de moyens et de suivi de proximité. | CP4: Manque de moyens et de suivi de proximité. | CQ4: Manque de moyens et de suivi de proximité. | CR4: oui
A5: 4 | B5: 13-14-15-16 | C5: CEG 6 Cotonou | D5: Abomey | E5: MONO | F5: Public | H5: 30-39 ans | I5: 5-10 ans | J5: ACDPE | L5: Master Pro | M5: Master | N5: Sciences et Technologies | P5: Non | Q5: 6 à 10 jours | R5: Oui | S5: 5 | T5: 0 | U5: 1 | V5: 0 | W5: 1 | X5: Aucun de ces équipements | Ordinateur/tablette | AB5: 5 | AC5: 5 | AD5: 3 | AE5: 1 | AF5: 2 | AG5: 2 | AH5: 1 | AI5: 0 | AJ5: 0 | AK5: 0 | AL5: 0 | AM5: 1 | AN5: Ministère | Autre | AO5: 3 | AP5: 4 | AQ5: 3 | AR5: 2 | AS5: 2 | AT5: 2 | AU5: 4 | AV5: 0 | AW5: 0 | AX5: 1 | AY5: 1 | AZ5: 0 | BA5: Réunion collective de suivi (conseil d'enseignement, animation pédagogique) | Mentorat/tutorat par un pair | BB5: 3 à 5 fois | BC5: 5 | BD5: 2 | BE5: 2 | BF5: 4 | BG5: 4 | BH5: 3 | BI5: 3 | BK5: 2 | BL5: 4 | BM5: 1 | BN5: 2 | BO5: 3 | BP5: 1 | BQ5: 3 | BS5: 2 | BT5: 3 | BU5: 5 | BV5: 4 | BW5: 3 | BX5: 5 | BY5: 5 | BZ5: 4 | CA5: Très souvent | CB5: 0 | CC5: 0 | CD5: 0 | CE5: 1 | CF5: Pas d'obstacle majeur | CG5: 2 | CH5: 5 | CI5: 3 | CJ5: 2 | CK5: Autre | CL5: Formation longue (plusieurs semaines continues) | CM5: Indifférent | CP5: Motiver les enseignants et former les encadreurs. | CR5: oui
A6: 5 | B6: 17-18-19-20 | C6: CEG 5 Abomey | D6: Abomey | E6: BORGOU | F6: Public | G6: Masculin | H6: 30-39 ans | I6: 11-20 ans | J6: AME | L6: Licence Pro | M6: Licence | N6: Autre | P6: Non | R6: Non | S6: 3 | T6: 1 | U6: 0 | V6: 1 | W6: 0 | X6: Connexion Internet à domicile | Smartphone | Y6: 3 | Z6: 2 | AA6: 4 | AB6: 5 | AC6: 4 | AE6: 5 | AF6: 3 | AH6: 0 | AI6: 0 | AJ6: 0 | AK6: 1 | AL6: 1 | AM6: 0 | AN6: Initiative personnelle | ONG/Partenaires | AO6: 3 | AP6: 5 | AR6: 4 | AS6: 3 | AT6: 5 | AU6: 3 | AV6: 0 | AW6: 1 | AX6: 0 | AY6: 0 | AZ6: 0 | BA6: Entretien individuel avec un encadreur | BB6: 1 à 2 fois | BC6: 3 | BD6: 2 | BF6: 5 | BG6: 2 | BH6: 4 | BI6: 5 | BK6: 4 | BL6: 2 | BM6: 2 | BN6: 3 | BO6: 5 | BP6: 4 | BQ6: 5 | BR6: 3 | BS6: 2 | BT6: 2 | BU6: 2 | BV6: 2 | BW6: 3 | BX6: 5 | BY6: 1 | BZ6: 5 | CA6: Jamais | CB6: 0 | CC6: 0 | CD6: 1 | CE6: 0 | CF6: Manque de compétences numériques | CG6: 3 | CH6: 4 | CI6: 3 | CJ6: 3 | CK6: Mixte (présentiel + à distance) | CL6: Modules répartis sur plusieurs semaines | CM6: Plutôt oui | CN6: Manque de moyens et de suivi de proximité. | CP6: Manque de moyens et de suivi de proximité. | CQ6: Manque de moyens et de suivi de proximité. | CR6: oui
A7: 6 | B7: 21-22-23-24 | C7: CEG 1 Porto-Novo | D7: Abomey | E7: BORGOU | F7: Privé | G7: Féminin | H7: 40-49 ans | I7: moins de 5 ans | J7: AME | L7: BAPES | M7: Master | N7: Sciences Humaines | P7: Non | Q7: Plus de 10 jours | R7: Non | S7: 1 | T7: 0 | U7: 1 | V7: 1 | W7: 0 | X7: Ordinateur/tablette | Connexion Internet à domicile | Y7: 1 | Z7: 5 | AA7: 3 | AB7: 4 | AC7: 2 | AD7: 1 | AE7: 3 | AG7: 3 | AH7: 1 | AI7: 0 | AJ7: 0 | AK7: 1 | AL7: 0 | AM7: 0 | AN7: Ministère | ONG/Partenaires | AO7: 4 | AP7: 1 | AQ7: 3 | AR7: 4 | AS7: 4 | AT7: 3 | AU7: 2 | AV7: 1 | AW7: 0 | AX7: 0 | AY7: 1 | AZ7: 0 | BA7: Réunion collective de suivi (conseil d'enseignement, animation pédagogique) | Visite de classe en situation | BB7: 3 à 5 fois | BC7: 2 | BD7: 5 | BE7: 3 | BF7: 5 | BG7: 5 | BH7: 5 | BI7: 4 | BJ7: 3 | BK7: 5 | BL7: 4 | BM7: 3 | BN7: 2 | BP7: 2 | BQ7: 1 | BR7: 5 | BS7: 5 | BT7: 2 | BU7: 5 | BV7: 2 | BW7: 1 | BX7: 2 | BY7: 3 | BZ7: 3 | CA7: Souvent | CB7: 0 | CC7: 0 | CD7: 1 | CE7: 0 | CF7: Manque de compétences numériques | CG7: 4 | CH7: 4 | CI7: 4 | CJ7: 5 | CK7: À distance (en ligne) | CL7: Une journée complète | CM7: Plutôt oui | CN7: Manque de moyens et de suivi de proximité. | CQ7: Motiver les enseignants et former les encadreurs. | CR7: oui
A8: 7 | B8: 25-26-27-28 | C8: CEG 8 Cotonou | D8: Porto-Novo | E8: OUEME | F8: Privé | G8: Féminin | H8: 50 ans et plus | I8: moins de 5 ans | J8: FE | L8: BAPES | M8: Maîtrise | N8: Sciences et Technologies | P8: Oui | Q8: 6 à 10 jours | R8: Non | S8: 3 | T8: 0 | U8: 1 | V8: 0 | W8: 0 | X8: Ordinateur/tablette | AB8: 4 | AC8: 4 | AD8: 5 | AE8: 1 | AF8: 4 | AG8: 3 | AH8: 0 | AI8: 1 | AJ8: 1 | AK8: 0 | AL8: 0 | AM8: 0 | AN8: Établissement | Inspection | AP8: 5 | AQ8: 4 | AR8: 3 | AS8: 5 | AT8: 2 | AV8: 1 | AW8: 1 | AX8: 0 | AY8: 0 | AZ8: 0 | BA8: Entretien individuel avec un encadreur | Visite de classe en situation | BB8: Jamais | BC8: 3 | BD8: 3 | BE8: 4 | BF8: 5 | BG8: 4 | BH8: 2 | BI8: 4 | BJ8: 3 | BK8: 4 | BL8: 5 | BM8: 4 | BN8: 3 | BO8: 1 | BP8: 4 | BQ8: 3 | BR8: 2 | BS8: 4 | BT8: 3 | BU8: 5 | BV8: 4 | BW8: 3 | BX8: 2 | BY8: 4 | BZ8: 1 | CA8: Parfois | CB8: 1 | CC8: 1 | CD8: 0 | CE8: 0 | CF8: Accès limité à Internet | Matériel insuffisant | CG8: 4 | CH8: 3 | CI8: 2 | CJ8: 3 | CK8: Présentiel pur | CL8: Deux jours consécutifs | CM8: Plutôt oui | CO8: Motiver les enseignants et former les encadreurs.
A9: 8 | B9: 29-30-31-32 | C9: CEG 1 Lokossa | D9: Porto-Novo | E9: BORGOU | F9: Privé | G9: Masculin | H9: 40-49 ans | I9: plus de 20 ans | J9: FE | L9: Master Pro | M9: Maîtrise | N9: Sciences et Technologies | P9: Non | Q9: 6 à 10 jours | R9: Oui | S9: 2 | T9: 0 | U9: 0 | V9: 1 | W9: 0 | X9: Connexion Internet à domicile | AB9: 3 | AD9: 3 | AE9: 2 | AF9: 2 | AG9: 4 | AH9: 0 | AI9: 0 | AJ9: 0 | AK9: 1 | AL9: 0 | AM9: 0 | AN9: ONG/Partenaires | AO9: 2 | AP9: 4 | AQ9: 5 | AR9: 2 | AS9: 2 | AT9: 5 | AU9: 3 | AV9: 0 | AW9: 0 | AX9: 1 | AY9: 0 | AZ9: 1 | BA9: Mentorat/tutorat par un pair | Aucun accompagnement reçu | BC9: 2 | BD9: 5 | BE9: 5 | BF9: 2 | BG9: 5 | BH9: 2 | BI9: 3 | BJ9: 1 | BK9: 3 | BL9: 2 | BM9: 2 | BN9: 5 | BO9: 4 | BP9: 1 | BQ9: 3 | BR9: 4 | BS9: 4 | BT9: 5 | BU9: 4 | BV9: 3 | BW9: 3 | BX9: 5 | BY9: 2 | BZ9: 3 | CA9: Parfois | CB9: 0 | CC9: 1 | CD9: 1 | CE9: 0 | CF9: Manque de compétences numériques | Matériel insuffisant | CG9: 2 | CH9: 1 | CI9: 4 | CJ9: 5 | CK9: Mixte (présentiel + à distance) | CL9: Une journée complète | CM9: Plutôt non | CN9: Manque de moyens et de suivi de proximité. | CO9: Motiver les enseignants et former les encadreurs. | CQ9: Motiver les enseignants et former les encadreurs. | CR9: oui
A10: 9 | B10: 33-34-35-36 | C10: CEG 5 Cotonou | D10: Lokossa | E10: LITTORAL | F10: Privé | G10: Masculin | H10: 30-39 ans | I10: 11-20 ans | J10: AME | L10: Master Pro | N10: Lettres | P10: Oui | Q10: 3 à 5 jours | R10: Non | S10: 2 | T10: 0 | U10: 0 | V10: 1 | W10: 1 | X10: Aucun de ces équipements | Connexion Internet à domicile | Y10: 2 | Z10: 2 | AA10: 4 | AB10: 3 | AC10: 4 | AD10: 3 | AE10: 4 | AF10: 1 | AG10: 4 | AH10: 0 | AI10: 0 | AJ10: 0 | AK10: 1 | AL10: 0 | AM10: 0 | AN10: ONG/Partenaires | AO10: 4 | AP10: 2 | AQ10: 5 | AR10: 4 | AS10: 4 | AT10: 3 | AU10: 1 | AV10: 0 | AW10: 1 | AX10: 0 | AY10: 0 | AZ10: 0 | BA10: Entretien individuel avec un encadreur | BB10: Jamais | BC10: 1 | BD10: 4 | BE10: 3 | BF10: 4 | BG10: 3 | BH10: 5 | BI10: 3 | BJ10: 5 | BK10: 2 | BL10: 2 | BM10: 4 | BN10: 4 | BO10: 4 | BP10: 5 | BQ10: 3 | BR10: 1 | BS10: 4 | BT10: 3 | BU10: 4 | BV10: 3 | BW10: 3 | BX10: 5 | BY10: 4 | BZ10: 2 | CA10: Jamais | CB10: 0 | CC10: 1 | CD10: 1 | CE10: 0 | CF10: Manque de compétences numériques | Matériel insuffisant | CG10: 3 | CH10: 5 | CI10: 3 | CJ10: 5 | CK10: Mixte (présentiel + à distance) | CL10: Modules répartis sur plusieurs semaines | CM10: Indifférent | CN10: Motiver les enseignants et former les encadreurs. | CP10: Manque de moyens et de suivi de proximité.
A11: 10 | B11: 37-38-39-40 | C11: CEG 6 Cotonou | D11: Porto-Novo | E11: BORGOU | F11: Privé | G11: Masculin | H11: 50 ans et plus | I11: moins de 5 ans | J11: AME | L11: CAPES | M11: Master | N11: Sciences Humaines | P11: Non | Q11: 6 à 10 jours | R11: Non | S11: 2 | T11: 0 | U11: 1 | V11: 0 | W11: 0 | X11: Ordinateur/tablette | Y11: 2 | Z11: 2 | AA11: 3 | AB11: 1 | AC11: 4 | AD11: 5 | AE11: 4 | AF11: 2 | AG11: 3 | AH11: 0 | AI11: 0 | AJ11: 0 | AK11: 0 | AL11: 0 | AM11: 1 | AN11: Autre | AO11: 4 | AP11: 3 | AQ11: 3 | AR11: 2 | AS11: 2 | AT11: 4 | AU11: 4 | AV11: 0 | AW11: 0 | AX11: 1 | AY11: 0 | AZ11: 0 | BA11: Mentorat/tutorat par un pair | BB11: Jamais | BC11: 3 | BD11: 2 | BE11: 1 | BF11: 1 | BG11: 3 | BH11: 3 | BI11: 3 | BJ11: 5 | BK11: 3 | BL11: 5 | BM11: 2 | BN11: 2 | BO11: 5 | BP11: 4 | BQ11: 4 | BR11: 3 | BS11: 4 | BT11: 4 | BU11: 3 | BV11: 4 | BW11: 5 | BX11: 4 | BY11: 1 | BZ11: 3 | CA11: Rarement | CB11: 0 | CC11: 1 | CD11: 0 | CE11: 0 | CF11: Matériel insuffisant | CG11: 1 | CH11: 1 | CI11: 5 | CJ11: 2 | CK11: Mixte (présentiel + à distance) | CL11: Formation longue (plusieurs semaines continues) | CM11: Oui, absolument | CN11: Motiver les enseignants et former les encadreurs. | CQ11: Manque de moyens et de suivi de proximité. | CR11: oui
A12: 11 | B12: 41-42-43-44 | C12: CEG 3 Parakou | D12: Porto-Novo | E12: LITTORAL | F12: Public | G12: Masculin | H12: 50 ans et plus | I12: moins de 5 ans | J12: FE | L12: CAPES | M12: Licence | N12: Sciences Humaines | P12: Non | Q12: 3 à 5 jours | R12: Oui | S12: 2 | T12: 0 | U12: 1 | V12: 0 | W12: 0 | X12: Ordinateur/tablette | AB12: 3 | AC12: 4 | AD12: 3 | AE12: 1 | AF12: 3 | AG12: 2 | AH12: 0 | AI12: 1 | AJ12: 1 | AK12: 0 | AL12: 0 | AM12: 0 | AN12: Établissement | Inspection | AO12: 4 | AP12: 3 | AQ12: 2 | AR12: 3 | AT12: 3 | AU12: 3 | AV12: 0 | AW12: 0 | AX12: 0 | AY12: 0 | AZ12: 1 | BA12: Aucun accompagnement reçu | BB12: Plus de 5 fois | BC12: 1 | BD12: 3 | BE12: 5 | BF12: 3 | BG12: 5 | BH12: 4 | BI12: 4 | BJ12: 3 | BK12: 2 | BL12: 4 | BM12: 4 | BN12: 1 | BO12: 2 | BP12: 4 | BQ12: 3 | BR12: 3 | BS12: 2 | BT12: 1 | BU12: 4 | BV12: 5 | BW12: 5 | BX12: 2 | BY12: 2 | BZ12: 5 | CA12: Jamais | CB12: 1 | CC12: 0 | CD12: 0 | CE12: 1 | CF12: Pas d'obstacle majeur | Accès limité à Internet | CG12: 5 | CH12: 4 | CI12: 5 | CJ12: 3 | CK12: Présentiel pur | CL12: Une journée complète | CM12: Non, pas nécessaire | CN12: Motiver les enseignants et former les encadreurs. | CO12: Motiver les enseignants et former les encadreurs. | CP12: Motiver les enseignants et former les encadreurs. | CQ12: Motiver les enseignants et former les encadreurs.
A13: 12 | B13: 45-46-47-48 | C13: CEG 8 Abomey | D13: Abomey | E13: ATACORA | F13: Privé | G13: Féminin | H13: 30-39 ans | I13: moins de 5 ans | J13: FE | L13: Master Pro | M13: BAC | N13: Autre | P13: Non | Q13: 3 à 5 jours | R13: Oui | T13: 1 | U13: 1 | V13: 0 | W13: 0 | X13: Ordinateur/tablette | Smartphone | AB13: 5 | AC13: 3 | AD13: 4 | AE13: 5 | AF13: 3 | AG13: 2 | AH13: 0 | AI13: 0 | AJ13: 0 | AK13: 0 | AL13: 1 | AM13: 1 | AN13: Initiative personnelle | Autre | AO13: 3 | AP13: 4 | AQ13: 3 | AR13: 3 | AS13: 3 | AT13: 4 | AU13: 5 | AV13: 0 | AW13: 1 | AX13: 0 | AY13: 1 | AZ13: 0 | BA13: Entretien individuel avec un encadreur | Réunion collective de suivi (conseil d'enseignement, animation pédagogique) | BB13: Plus de 5 fois | BC13: 3 | BD13: 3 | BE13: 2 | BF13: 5 | BG13: 4 | BH13: 2 | BJ13: 3 | BK13: 4 | BL13: 5 | BM13: 3 | BN13: 3 | BO13: 5 | BP13: 1 | BQ13: 2 | BR13: 4 | BS13: 3 | BT13: 4 | BU13: 4 | BV13: 1 | BW13: 2 | BX13: 1 | BY13: 3 | BZ13: 4 | CA13: Souvent | CB13: 0 | CC13: 1 | CD13: 0 | CE13: 0 | CF13: Matériel insuffisant | CG13: 3 | CH13: 4 | CI13: 3 | CJ13: 3 | CK13: Mixte (présentiel + à distance) | CL13: Deux jours consécutifs | CM13: Oui, absolument | CN13: Motiver les enseignants et former les encadreurs. | CQ13: Motiver les enseignants et former les encadreurs.
A14: 13 | B14: 49-50-51-52 | C14: CEG 4 Cotonou | D14: Parakou | E14: MONO | F14: Public | G14: Féminin | H14: 40-49 ans | I14: 11-20 ans | J14: ACDPE | L14: BAPES | M14: BAC | N14: Sciences et Technologies | P14: Oui | Q14: Plus de 10 jours | R14: Non | S14: 5 | T14: 1 | U14: 0 | V14: 0 | W14: 1 | X14: Smartphone | Aucun de ces équipements | AB14: 3 | AC14: 4 | AD14: 3 | AE14: 1 | AF14: 4 | AG14: 3 | AH14: 0 | AI14: 1 | AJ14: 0 | AK14: 0 | AL14: 1 | AM14: 0 | AN14: Initiative personnelle | Inspection | AO14: 4 | AP14: 4 | AQ14: 3 | AR14: 5 | AS14: 1 | AT14: 4 | AU14: 4 | AV14: 1 | AW14: 0 | AX14: 0 | AY14: 0 | AZ14: 1 | BA14: Visite de classe en situation | Aucun accompagnement reçu | BB14: Plus de 5 fois | BC14: 5 | BD14: 1 | BE14: 1 | BF14: 3 | BG14: 3 | BH14: 4 | BI14: 5 | BJ14: 2 | BK14: 3 | BL14: 4 | BM14: 3 | BN14: 3 | BO14: 3 | BP14: 5 | BQ14: 4 | BR14: 4 | BS14: 4 | BT14: 3 | BU14: 3 | BV14: 2 | BW14: 3 | BX14: 3 | BY14: 1 | BZ14: 2 | CA14: Rarement | CB14: 1 | CC14: 0 | CD14: 0 | CE14: 0 | CF14: Accès limité à Internet | CG14: 5 | CH14: 3 | CI14: 5 | CJ14: 5 | CK14: Autre | CL14: Deux jours consécutifs | CM14: Non, pas nécessaire | CN14: Motiver les enseignants et former les encadreurs. | CO14: Manque de moyens et de suivi de proximité. | CQ14: Manque de moyens et de suivi de proximité. | CR14: oui
A15: 14 | B15: 53-54-55-56 | C15: CEG 5 Porto-Novo | D15: Cotonou | E15: MONO | F15: Privé | G15: Féminin | H15: moins de 30 ans | I15: moins de 5 ans | J15: FE | L15: Licence Pro | M15: Maîtrise | N15: Autre | P15: Oui | Q15: 3 à 5 jours | R15: Oui | S15: Sans objet | T15: 0 | U15: 1 | V15: 1 | W15: 0 | X15: Connexion Internet à domicile | Ordinateur/tablette | AB15: 4 | AC15: 3 | AD15: 4 | AE15: 1 | AF15: 2 | AG15: 3 | AH15: 0 | AI15: 0 | AJ15: 0 | AK15: 1 | AL15: 0 | AM15: 0 | AN15: ONG/Partenaires | AO15: 5 | AP15: 3 | AQ15: 5 | AR15: 3 | AS15: 4 | AT15: 2 | AU15: 4 | AV15: 0 | AW15: 0 | AX15: 0 | AY15: 1 | AZ15: 0 | BA15: Réunion collective de suivi (conseil d'enseignement, animation pédagogique) | BB15: Plus de 5 fois | BC15: 4 | BD15: 4 | BE15: 4 | BF15: 2 | BG15: 3 | BH15: 1 | BI15: 2 | BJ15: 1 | BK15: 4 | BL15: 3 | BM15: 5 | BN15: 5 | BP15: 3 | BQ15: 2 | BR15: 1 | BS15: 4 | BT15: 4 | BU15: 2 | BV15: 3 | BW15: 4 | BX15: 2 | BY15: 3 | BZ15: 1 | CA15: Souvent | CB15: 1 | CC15: 1 | CD15: 0 | CE15: 0 | CF15: Accès limité à Internet | Matériel insuffisant | CG15: 3 | CH15: 3 | CI15: 3 | CJ15: 2 | CK15: À distance (en ligne) | CL15: Formation longue (plusieurs semaines continues) | CM15: Plutôt oui | CN15: Motiver les enseignants et former les encadreurs. | CO15: Manque de moyens et de suivi de proximité. | CP15: Manque de moyens et de suivi de proximité. | CQ15: Motiver les enseignants et former les encadreurs. | CR15: oui
A16: 15 | B16: 57-58-59-60 | C16: CEG 7 Porto-Novo | D16: Porto-Novo | E16: OUEME | F16: Privé | H16: 50 ans et plus | I16: 11-20 ans | J16: AME | L16: CAPES | N16: Sciences et Technologies | P16: Non | Q16: 3 à 5 jours | R16: Non | S16: 3 | T16: 1 | U16: 0 | V16: 0 | W16: 1 | X16: Aucun de ces équipements | Smartphone | Y16: 4 | Z16: 3 | AA16: 4 | AB16: 3 | AC16: 2 | AD16: 3 | AE16: 4 | AF16: 2 | AG16: 3 | AH16: 1 | AI16: 0 | AJ16: 0 | AK16: 0 | AL16: 0 | AM16: 1 | AN16: Autre | Ministère | AO16: 1 | AP16: 4 | AQ16: 3 | AR16: 1 | AS16: 2 | AT16: 4 | AU16: 5 | AV16: 0 | AW16: 1 | AX16: 0 | AY16: 0 | AZ16: 1 | BA16: Entretien individuel avec un encadreur | Aucun accompagnement reçu | BB16: Plus de 5 fois | BC16: 4 | BD16: 5 | BE16: 3 | BF16: 4 | BG16: 4 | BH16: 2 | BI16: 4 | BJ16: 3 | BK16: 1 | BL16: 4 | BM16: 3 | BN16: 3 | BO16: 5 | BP16: 2 | BQ16: 4 | BR16: 5 | BS16: 3 | BT16: 2 | BU16: 4 | BV16: 2 | BW16: 5 | BX16: 4 | BY16: 3 | BZ16: 3 | CA16: Rarement | CB16: 1 | CC16: 0 | CD16: 1 | CE16: 0 | CF16: Manque de compétences numériques | Accès limité à Internet | CG16: 3 | CH16: 2 | CI16: 4 | CJ16: 4 | CK16: À distance (en ligne) | CL16: Modules répartis sur plusieurs semaines | CM16: Non, pas nécessaire | CP16: Manque de moyens et de suivi de proximité.
A17: 16 | B17: 61-62-63-64 | C17: CEG 2 Porto-Novo | D17: Lokossa | E17: ATACORA | F17: Privé | H17: 30-39 ans | I17: moins de 5 ans | J17: ACDPE | L17: CAPES | M17: Licence | N17: Sciences et Technologies | P17: Non | Q17: Plus de 10 jours | R17: Non | S17: 2 | T17: 1 | U17: 0 | V17: 0 | W17: 1 | X17: Smartphone | Aucun de ces équipements | AB17: 4 | AC17: 4 | AD17: 2 | AF17: 5 | AG17: 2 | AH17: 0 | AI17: 0 | AJ17: 1 | AK17: 0 | AL17: 0 | AM17: 0 | AN17: Établissement | AO17: 3 | AP17: 4 | AQ17: 3 | AR17: 2 | AS17: 3 | AT17: 2 | AU17: 1 | AV17: 1 | AW17: 0 | AX17: 0 | AY17: 1 | AZ17: 0 | BA17: Visite de classe en situation | Réunion collective de suivi (conseil d'enseignement, animation pédagogique) | BB17: 1 à 2 fois | BC17: 4 | BD17: 5 | BE17: 4 | BF17: 4 | BG17: 4 | BH17: 5 | BI17: 2 | BJ17: 3 | BK17: 3 | BL17: 3 | BM17: 4 | BN17: 4 | BO17: 3 | BP17: 3 | BQ17: 2 | BR17: 2 | BS17: 1 | BT17: 5 | BU17: 4 | BV17: 5 | BW17: 5 | BX17: 3 | BY17: 1 | BZ17: 2 | CA17: Jamais | CB17: 1 | CC17: 0 | CD17: 1 | CE17: 0 | CF17: Accès limité à Internet | Manque de compétences numériques | CG17: 1 | CH17: 3 | CI17: 4 | CJ17: 3 | CK17: Présentiel pur | CL17: Modules répartis sur plusieurs semaines | CM17: Indifférent | CP17: Motiver les enseignants et former les encadreurs.
A18: 17 | B18: 65-66-67-68 | C18: CEG 9 Cotonou | D18: Porto-Novo | E18: ZOU | F18: Public | G18: Masculin | H18: moins de 30 ans | I18: moins de 5 ans | J18: FE | L18: BAPES | M18: BAC | N18: Lettres | P18: Oui | Q18: 6 à 10 jours | R18: Oui | S18: 2 | T18: 1 | U18: 0 | V18: 1 | W18: 0 | X18: Connexion Internet à domicile | Smartphone | AB18: 2 | AC18: 4 | AD18: 4 | AE18: 3 | AF18: 4 | AG18: 1 | AH18: 0 | AI18: 0 | AJ18: 0 | AK18: 0 | AL18: 0 | AM18: 1 | AN18: Autre | AO18: 4 | AP18: 3 | AS18: 1 | AT18: 2 | AV18: 0 | AW18: 0 | AX18: 1 | AY18: 0 | AZ18: 1 | BA18: Aucun accompagnement reçu | Mentorat/tutorat par un pair | BB18: Plus de 5 fois | BC18: 5 | BD18: 4 | BE18: 2 | BF18: 2 | BG18: 4 | BH18: 2 | BI18: 2 | BJ18: 3 | BK18: 3 | BL18: 3 | BM18: 3 | BN18: 2 | BO18: 3 | BP18: 5 | BQ18: 2 | BR18: 2 | BS18: 5 | BT18: 4 | BU18: 3 | BV18: 5 | BW18: 5 | BY18: 3 | BZ18: 5 | CA18: Très souvent | CB18: 0 | CC18: 0 | CD18: 1 | CE18: 0 | CF18: Manque de compétences numériques | CG18: 3 | CI18: 5 | CJ18: 3 | CK18: Mixte (présentiel + à distance) | CL18: Deux jours consécutifs | CM18: Plutôt oui | CN18: Motiver les enseignants et former les encadreurs. | CO18: Manque de moyens et de suivi de proximité. | CQ18: Manque de moyens et de suivi de proximité. | CR18: oui
A19: 18 | B19: 69-70-71-72 | C19: CEG 9 Abomey | D19: Cotonou | E19: OUEME | F19: Privé | G19: Masculin | I19: plus de 20 ans | J19: AME | M19: Licence | N19: Lettres | P19: Oui | Q19: 3 à 5 jours | R19: Oui | T19: 1 | U19: 0 | V19: 0 | W19: 1 | X19: Aucun de ces équipements | Smartphone | Y19: 3 | Z19: 5 | AA19: 3 | AB19: 4 | AC19: 2 | AD19: 5 | AE19: 2 | AF19: 4 | AG19: 4 | AH19: 1 | AI19: 0 | AJ19: 0 | AK19: 0 | AL19: 0 | AM19: 1 | AN19: Autre | Ministère | AO19: 3 | AP19: 5 | AQ19: 3 | AR19: 4 | AS19: 3 | AT19: 2 | AU19: 4 | AV19: 0 | AW19: 0 | AX19: 0 | AY19: 1 | AZ19: 0 | BA19: Réunion collective de suivi (conseil d'enseignement, animation pédagogique) | BB19: Jamais | BC19: 3 | BD19: 2 | BE19: 2 | BF19: 3 | BG19: 3 | BH19: 2 | BI19: 5 | BJ19: 5 | BK19: 4 | BL19: 5 | BM19: 3 | BN19: 5 | BO19: 5 | BP19: 2 | BQ19: 3 | BR19: 5 | BS19: 4 | BT19: 2 | BU19: 2 | BV19: 2 | BW19: 4 | BX19: 3 | BY19: 4 | BZ19: 2 | CA19: Souvent | CB19: 0 | CC19: 1 | CD19: 0 | CE19: 1 | CF19: Pas d'obstacle majeur | Matériel insuffisant | CG19: 3 | CH19: 4 | CI19: 4 | CJ19: 3 | CK19: À distance (en ligne) | CL19: Une journée complète | CM19: Non, pas nécessaire | CN19: Motiver les enseignants et former les encadreurs. | CO19: Manque de moyens et de suivi de proximité. | CP19: Motiver les enseignants et former les encadreurs.
A20: 19 | B20: 73-74-75-76 | C20: CEG 7 Abomey | D20: Cotonou | E20: BORGOU | F20: Privé | G20: Masculin | H20: 50 ans et plus | I20: 5-10 ans | J20: ACDPE | L20: Master Pro | M20: Master | N20: Sciences Humaines | P20: Non | Q20: 3 à 5 jours | R20: Non | S20: 1 | T20: 1 | U20: 0 | V20: 0 | W20: 1 | X20: Aucun de ces équipements | Smartphone | AB20: 3 | AC20: 5 | AD20: 5 | AE20: 5 | AF20: 3 | AG20: 3 | AH20: 0 | AI20: 1 | AJ20: 0 | AK20: 0 | AL20: 0 | AM20: 1 | AN20: Inspection | Autre | AO20: 3 | AP20: 5 | AQ20: 5 | AR20: 3 | AS20: 1 | AT20: 5 | AU20: 3 | AV20: 1 | AW20: 0 | AX20: 0 | AY20: 1 | AZ20: 0 | BA20: Visite de classe en situation | Réunion collective de suivi (conseil d'enseignement, animation pédagogique) | BB20: 1 à 2 fois | BC20: 5 | BD20: 5 | BE20: 4 | BF20: 2 | BG20: 4 | BH20: 2 | BI20: 5 | BJ20: 3 | BK20: 1 | BL20: 3 | BM20: 3 | BN20: 2 | BP20: 5 | BQ20: 4 | BR20: 4 | BS20: 1 | BT20: 3 | BU20: 2 | BV20: 5 | BW20: 4 | BX20: 1 | BY20: 1 | BZ20: 4 | CA20: Souvent | CB20: 0 | CC20: 1 | CD20: 1 | CE20: 0 | CF20: Manque de compétences numériques | Matériel insuffisant | CG20: 2 | CH20: 2 | CI20: 4 | CJ20: 4 | CK20: Mixte (présentiel + à distance) | CL20: Modules répartis sur plusieurs semaines | CM20: Plutôt non | CP20: Motiver les enseignants et former les encadreurs. | CQ20: Motiver les enseignants et former les encadreurs.
A21: 20 | B21: 77-78-79-80 | C21: CEG 3 Lokossa | D21: Porto-Novo | E21: ZOU | F21: Public | G21: Masculin | H21: 50 ans et plus | I21: 5-10 ans | J21: AME | L21: CAPES | M21: Licence | N21: Lettres | P21: Non | Q21: 6 à 10 jours | R21: Non | S21: 5 | T21: 1 | U21: 0 | V21: 0 | W21: 0 | X21: Smartphone | Y21: 1 | Z21: 2 | AA21: 4 | AB21: 4 | AC21: 2 | AD21: 3 | AE21: 4 | AF21: 2 | AG21: 2 | AH21: 1 | AI21: 0 | AJ21: 0 | AK21: 1 | AL21: 0 | AM21: 0 | AN21: ONG/Partenaires | Ministère | AO21: 3 | AP21: 4 | AQ21: 4 | AR21: 1 | AS21: 3 | AT21: 3 | AU21: 5 | AV21: 1 | AW21: 0 | AX21: 0 | AY21: 0 | AZ21: 0 | BA21: Visite de classe en situation | BB21: 1 à 2 fois | BC21: 3 | BD21: 4 | BE21: 3 | BF21: 3 | BG21: 3 | BH21: 3 | BI21: 1 | BJ21: 5 | BK21: 3 | BL21: 3 | BM21: 1 | BN21: 3 | BO21: 4 | BP21: 5 | BQ21: 4 | BR21: 5 | BS21: 5 | BT21: 5 | BU21: 2 | BV21: 5 | BW21: 5 | BX21: 2 | BY21: 4 | BZ21: 3 | CA21: Très souvent | CB21: 0 | CC21: 1 | CD21: 0 | CE21: 0 | CF21: Matériel insuffisant | CG21: 1 | CH21: 5 | CI21: 5 | CJ21: 2 | CK21: À distance (en ligne) | CL21: Deux jours consécutifs | CM21: Non, pas nécessaire | CO21: Motiver les enseignants et former les encadreurs. | CP21: Motiver les enseignants et former les encadreurs. | CR21: oui
A22: 21 | B22: 81-82-83-84 | C22: CEG 8 Parakou | D22: Parakou | E22: BORGOU | F22: Privé | G22: Masculin | H22: 50 ans et plus | I22: 11-20 ans | J22: AME | L22: CAPES | M22: Licence | N22: Lettres | P22: Oui | Q22: 6 à 10 jours | R22: Non | S22: 3 | T22: 0 | U22: 1 | V22: 1 | W22: 0 | X22: Ordinateur/tablette | Connexion Internet à domicile | Y22: 5 | Z22: 3 | AA22: 4 | AB22: 5 | AC22: 1 | AD22: 4 | AE22: 4 | AF22: 2 | AG22: 4 | AH22: 0 | AI22: 1 | AJ22: 0 | AK22: 1 | AL22: 0 | AM22: 0 | AN22: Inspection | ONG/Partenaires | AO22: 3 | AP22: 2 | AQ22: 4 | AR22: 4 | AS22: 4 | AT22: 3 | AU22: 3 | AV22: 1 | AW22: 0 | AX22: 0 | AY22: 0 | AZ22: 1 | BA22: Aucun accompagnement reçu | Visite de classe en situation | BB22: Plus de 5 fois | BC22: 3 | BD22: 4 | BE22: 4 | BF22: 2 | BG22: 5 | BH22: 4 | BI22: 5 | BJ22: 4 | BK22: 2 | BL22: 1 | BM22: 3 | BN22: 5 | BO22: 4 | BP22: 3 | BQ22: 3 | BR22: 2 | BS22: 3 | BT22: 1 | BU22: 3 | BV22: 4 | BW22: 3 | BX22: 4 | BY22: 4 | BZ22: 2 | CA22: Souvent | CB22: 1 | CC22: 1 | CD22: 0 | CE22: 0 | CF22: Accès limité à Internet | Matériel insuffisant | CG22: 5 | CH22: 3 | CI22: 2 | CJ22: 3 | CK22: Mixte (présentiel + à distance) | CL22: Une journée complète | CM22: Plutôt oui | CO22: Manque de moyens et de suivi de proximité. | CP22: Manque de moyens et de suivi de proximité. | CR22: oui
A23: 22 | B23: 85-86-87-88 | C23: CEG 3 Porto-Novo | D23: Cotonou | E23: ATACORA | F23: Privé | G23: Féminin | H23: 50 ans et plus | I23: moins de 5 ans | J23: AME | L23: CAPES | M23: Maîtrise | N23: Sciences Humaines | P23: Non | Q23: 1 à 2 jours | R23: Non | S23: 1 | T23: 0 | U23: 0 | V23: 1 | W23: 0 | X23: Connexion Internet à domicile | Y23: 4 | Z23: 4 | AA23: 3 | AB23: 2 | AC23: 4 | AD23: 2 | AE23: 5 | AF23: 2 | AG23: 2 | AH23: 0 | AI23: 0 | AJ23: 0 | AK23: 1 | AL23: 0 | AM23: 0 | AN23: ONG/Partenaires | AO23: 2 | AP23: 3 | AQ23: 3 | AR23: 4 | AS23: 3 | AT23: 4 | AU23: 2 | AV23: 0 | AW23: 0 | AX23: 1 | AY23: 0 | AZ23: 0 | BA23: Mentorat/tutorat par un pair | BB23: 3 à 5 fois | BC23: 5 | BD23: 4 | BE23: 3 | BF23: 1 | BG23: 5 | BH23: 3 | BI23: 2 | BJ23: 3 | BK23: 2 | BL23: 3 | BM23: 4 | BN23: 5 | BO23: 2 | BP23: 1 | BQ23: 2 | BR23: 4 | BS23: 3 | BT23: 4 | BU23: 5 | BV23: 4 | BW23: 3 | BX23: 2 | BY23: 5 | BZ23: 5 | CA23: Souvent | CB23: 1 | CC23: 1 | CD23: 0 | CE23: 0 | CF23: Accès limité à Internet | Matériel insuffisant | CG23: 4 | CH23: 3 | CI23: 5 | CJ23: 4 | CK23: Mixte (présentiel + à distance) | CL23: Formation longue (plusieurs semaines continues) | CM23: Indifférent | CP23: Manque de moyens et de suivi de proximité.
A24: 23 | B24: 89-90-91-92 | C24: CEG 8 Natitingou | D24: Abomey | E24: ATACORA | F24: Privé | G24: Masculin | H24: 50 ans et plus | I24: plus de 20 ans | J24: AME | L24: BAPES | M24: Master | N24: Autre | P24: Non | Q24: 3 à 5 jours | R24: Non | S24: 5 | T24: 1 | U24: 0 | V24: 0 | W24: 0 | X24: Smartphone | Y24: 5 | Z24: 1 | AA24: 3 | AB24: 1 | AC24: 5 | AD24: 4 | AE24: 4 | AF24: 2 | AG24: 4 | AH24: 1 | AI24: 0 | AJ24: 0 | AK24: 1 | AL24: 0 | AM24: 0 | AN24: Ministère | ONG/Partenaires | AO24: 4 | AP24: 5 | AQ24: 4 | AR24: 4 | AS24: 3 | AT24: 5 | AU24: 1 | AV24: 0 | AW24: 1 | AX24: 0 | AY24: 0 | AZ24: 0 | BA24: Entretien individuel avec un encadreur | BB24: Plus de 5 fois | BC24: 4 | BD24: 3 | BE24: 3 | BF24: 4 | BG24: 5 | BH24: 3 | BI24: 4 | BJ24: 5 | BK24: 4 | BL24: 3 | BM24: 5 | BN24: 3 | BO24: 2 | BP24: 5 | BQ24: 1 | BR24: 3 | BS24: 2 | BT24: 5 | BU24: 5 | BV24: 4 | BW24: 3 | BX24: 1 | BZ24: 1 | CA24: Très souvent | CB24: 0 | CC24: 0 | CD24: 1 | CE24: 0 | CF24: Manque de compétences numériques | CG24: 5 | CH24: 4 | CI24: 3 | CJ24: 3 | CK24: Présentiel pur | CL24: Formation longue (plusieurs semaines continues) | CM24: Oui, absolument | CN24: Manque de moyens et de suivi de proximité. | CO24: Manque de moyens et de suivi de proximité. | CP24: Motiver les enseignants et former les encadreurs.
A25: 24 | B25: 93-94-95-96 | C25: CEG 4 Parakou | D25: Lokossa | E25: LITTORAL | F25: Privé | G25: Féminin | H25: 40-49 ans | I25: plus de 20 ans | J25: AME | L25: BAPES | M25: Maîtrise | N25: Sciences et Technologies | P25: Oui | Q25: 1 à 2 jours | R25: Oui | S25: 1 | T25: 0 | U25: 0 | V25: 0 | W25: 1 | X25: Aucun de ces équipements | Y25: 4 | Z25: 3 | AA25: 3 | AB25: 5 | AC25: 4 | AD25: 5 | AE25: 5 | AF25: 2 | AG25: 3 | AH25: 0 | AI25: 0 | AJ25: 0 | AK25: 1 | AL25: 0 | AM25: 0 | AN25: ONG/Partenaires | AO25: 4 | AP25: 2 | AQ25: 3 | AR25: 5 | AS25: 3 | AT25: 2 | AU25: 3 | AV25: 0 | AW25: 1 | AX25: 1 | AY25: 0 | AZ25: 0 | BA25: Entretien individuel avec un encadreur | Mentorat/tutorat par un pair | BB25: Plus de 5 fois | BC25: 5 | BD25: 1 | BE25: 2 | BF25: 5 | BG25: 1 | BH25: 4 | BI25: 4 | BJ25: 3 | BK25: 3 | BL25: 4 | BM25: 4 | BN25: 2 | BO25: 3 | BP25: 4 | BQ25: 4 | BR25: 1 | BS25: 2 | BT25: 3 | BU25: 4 | BV25: 5 | BW25: 2 | BX25: 2 | BY25: 3 | CA25: Rarement | CB25: 0 | CC25: 0 | CD25: 1 | CE25: 0 | CF25: Manque de compétences numériques | CH25: 2 | CI25: 1 | CJ25: 4 | CK25: Présentiel pur | CL25: Deux jours consécutifs | CM25: Plutôt oui | CN25: Motiver les enseignants et former les encadreurs. | CP25: Manque de moyens et de suivi de proximité. | CQ25: Motiver les enseignants et former les encadreurs. | CR25: oui
A26: 25 | B26: 97-98-99-100 | C26: CEG 1 Natitingou | D26: Cotonou | E26: MONO | F26: Public | G26: Masculin | H26: 30-39 ans | I26: moins de 5 ans | J26: AME | L26: Licence Pro | M26: Master | N26: Autre | P26: Non | Q26: 3 à 5 jours | R26: Oui | S26: 1 | T26: 0 | U26: 1 | V26: 0 | W26: 0 | X26: Ordinateur/tablette | Y26: 2 | Z26: 4 | AA26: 3 | AB26: 2 | AC26: 4 | AD26: 3 | AE26: 3 | AF26: 5 | AG26: 4 | AH26: 0 | AI26: 0 | AJ26: 0 | AK26: 0 | AL26: 0 | AM26: 1 | AN26: Autre | AO26: 3 | AP26: 3 | AQ26: 1 | AR26: 1 | AS26: 1 | AT26: 5 | AU26: 4 | AV26: 0 | AW26: 0 | AX26: 1 | AY26: 0 | AZ26: 0 | BA26: Mentorat/tutorat par un pair | BB26: Jamais | BC26: 2 | BD26: 5 | BE26: 3 | BF26: 5 | BG26: 1 | BH26: 2 | BI26: 1 | BJ26: 4 | BK26: 1 | BL26: 5 | BM26: 3 | BN26: 5 | BO26: 5 | BP26: 5 | BQ26: 1 | BR26: 5 | BS26: 5 | BT26: 4 | BU26: 2 | BV26: 2 | BW26: 2 | BX26: 3 | BY26: 5 | BZ26: 4 | CA26: Très souvent | CB26: 0 | CC26: 1 | CD26: 0 | CE26: 1 | CF26: Matériel insuffisant | Pas d'obstacle majeur | CG26: 2 | CH26: 2 | CI26: 2 | CJ26: 3 | CK26: Présentiel pur | CL26: Une journée complète | CM26: Non, pas nécessaire | CN26: Manque de moyens et de suivi de proximité. | CO26: Manque de moyens et de suivi de proximité. | CP26: Motiver les enseignants et former les encadreurs. | CQ26: Motiver les enseignants et former les encadreurs. | CR26: oui
A27: 26 | B27: 101-102-103-104 | C27: CEG 8 Parakou | D27: Lokossa | E27: BORGOU | F27: Privé | G27: Féminin | H27: moins de 30 ans | I27: 11-20 ans | J27: ACDPE | M27: Licence | N27: Sciences et Technologies | P27: Non | Q27: Plus de 10 jours | R27: Oui | S27: Sans objet | T27: 1 | U27: 0 | V27: 1 | W27: 0 | X27: Connexion Internet à domicile | Smartphone | AB27: 2 | AC27: 4 | AD27: 5 | AE27: 4 | AF27: 5 | AG27: 5 | AH27: 0 | AI27: 0 | AJ27: 1 | AK27: 0 | AL27: 1 | AM27: 0 | AN27: Initiative personnelle | Établissement | AO27: 3 | AP27: 5 | AQ27: 4 | AR27: 3 | AS27: 1 | AT27: 3 | AV27: 0 | AW27: 0 | AX27: 0 | AY27: 1 | AZ27: 1 | BA27: Aucun accompagnement reçu | Réunion collective de suivi (conseil d'enseignement, animation pédagogique) | BB27: Plus de 5 fois | BC27: 3 | BD27: 1 | BE27: 4 | BF27: 2 | BG27: 2 | BH27: 3 | BI27: 3 | BJ27: 4 | BK27: 4 | BL27: 3 | BM27: 3 | BN27: 5 | BO27: 1 | BP27: 5 | BQ27: 5 | BR27: 5 | BS27: 2 | BT27: 5 | BU27: 2 | BV27: 3 | BW27: 4 | BX27: 4 | BY27: 4 | BZ27: 5 | CA27: Parfois | CB27: 1 | CC27: 0 | CD27: 0 | CE27: 0 | CF27: Accès limité à Internet | CG27: 2 | CH27: 3 | CI27: 3 | CJ27: 1 | CK27: Autre | CL27: Deux jours consécutifs | CM27: Oui, absolument | CN27: Manque de moyens et de suivi de proximité. | CO27: Manque de moyens et de suivi de proximité. | CP27: Manque de moyens et de suivi de proximité. | CR27: oui
A28: 27 | B28: 105-106-107-108 | C28: CEG 2 Porto-Novo | D28: Cotonou | E28: MONO | F28: Public | G28: Masculin | H28: 40-49 ans | J28: FE | L28: Licence Pro | M28: BAC | N28: Autre | P28: Oui | R28: Oui | S28: 2 | T28: 0 | U28: 0 | V28: 1 | W28: 0 | X28: Connexion Internet à domicile | AC28: 5 | AD28: 3 | AE28: 2 | AF28: 2 | AG28: 3 | AH28: 0 | AI28: 0 | AJ28: 0 | AK28: 0 | AL28: 1 | AM28: 0 | AN28: Initiative personnelle | AO28: 1 | AP28: 2 | AR28: 3 | AS28: 2 | AT28: 5 | AU28: 3 | AV28: 0 | AW28: 0 | AX28: 0 | AY28: 0 | AZ28: 1 | BA28: Aucun accompagnement reçu | BB28: Plus de 5 fois | BC28: 3 | BD28: 3 | BE28: 2 | BF28: 4 | BG28: 4 | BH28: 4 | BI28: 4 | BJ28: 1 | BK28: 1 | BL28: 5 | BM28: 1 | BN28: 2 | BO28: 4 | BP28: 4 | BQ28: 3 | BR28: 2 | BS28: 4 | BT28: 3 | BU28: 4 | BV28: 4 | BW28: 2 | BX28: 3 | BZ28: 1 | CA28: Souvent | CB28: 1 | CC28: 0 | CD28: 1 | CE28: 0 | CF28: Manque de compétences numériques | Accès limité à Internet | CG28: 5 | CH28: 3 | CI28: 3 | CJ28: 3 | CK28: Présentiel pur | CL28: Une journée complète | CM28: Plutôt non | CN28: Motiver les enseignants et former les encadreurs. | CO28: Manque de moyens et de suivi de proximité. | CQ28: Manque de moyens et de suivi de proximité.
A29: 28 | B29: 109-110-111-112 | C29: CEG 9 Natitingou | D29: Parakou | E29: BORGOU | F29: Public | G29: Masculin | H29: 30-39 ans | I29: 5-10 ans | J29: AME | L29: BAPES | M29: Licence | N29: Sciences Humaines | P29: Non | Q29: Plus de 10 jours | R29: Oui | S29: 2 | T29: 1 | U29: 0 | V29: 1 | W29: 0 | X29: Smartphone | Connexion Internet à domicile | Y29: 5 | Z29: 5 | AB29: 3 | AC29: 4 | AD29: 2 | AE29: 5 | AF29: 2 | AH29: 0 | AI29: 0 | AJ29: 1 | AK29: 0 | AL29: 1 | AM29: 0 | AN29: Initiative personnelle | Établissement | AO29: 2 | AP29: 4 | AQ29: 4 | AR29: 3 | AS29: 2 | AT29: 2 | AU29: 1 | AV29: 1 | AW29: 0 | AX29: 0 | AY29: 1 | AZ29: 0 | BA29: Réunion collective de suivi (conseil d'enseignement, animation pédagogique) | Visite de classe en situation | BC29: 1 | BD29: 2 | BE29: 3 | BF29: 4 | BH29: 5 | BI29: 2 | BK29: 3 | BL29: 4 | BM29: 3 | BN29: 4 | BO29: 4 | BP29: 3 | BQ29: 5 | BR29: 4 | BS29: 4 | BT29: 4 | BU29: 4 | BV29: 5 | BW29: 5 | BX29: 4 | BY29: 3 | BZ29: 5 | CA29: Jamais | CB29: 0 | CC29: 1 | CD29: 1 | CE29: 0 | CF29: Matériel insuffisant | Manque de compétences numériques | CG29: 3 | CH29: 5 | CI29: 2 | CJ29: 1 | CK29: Mixte (présentiel + à distance) | CL29: Deux jours consécutifs | CM29: Oui, absolument | CO29: Motiver les enseignants et former les encadreurs. | CQ29: Motiver les enseignants et former les encadreurs. | CR29: oui
A30: 29 | B30: 113-114-115-116 | C30: CEG 4 Cotonou | D30: Lokossa | E30: OUEME | F30: Public | G30: Masculin | H30: 50 ans et plus | I30: plus de 20 ans | J30: ACDPE | M30: Licence | N30: Lettres | P30: Non | Q30: 1 à 2 jours | R30: Non | S30: 1 | T30: 0 | U30: 1 | V30: 0 | W30: 1 | X30: Aucun de ces équipements | Ordinateur/tablette | AB30: 4 | AC30: 3 | AD30: 3 | AE30: 3 | AF30: 3 | AG30: 5 | AH30: 1 | AI30: 0 | AJ30: 0 | AK30: 1 | AL30: 0 | AM30: 0 | AN30: ONG/Partenaires | Ministère | AP30: 3 | AQ30: 4 | AR30: 4 | AS30: 5 | AT30: 4 | AU30: 1 | AV30: 1 | AW30: 0 | AX30: 0 | AY30: 0 | AZ30: 0 | BA30: Visite de classe en situation | BB30: Jamais | BC30: 1 | BD30: 2 | BE30: 5 | BF30: 4 | BH30: 4 | BI30: 3 | BJ30: 2 | BK30: 2 | BL30: 4 | BM30: 1 | BN30: 3 | BO30: 4 | BP30: 2 | BQ30: 5 | BR30: 5 | BS30: 4 | BT30: 4 | BU30: 1 | BV30: 4 | BW30: 5 | BX30: 4 | BY30: 4 | BZ30: 4 | CA30: Très souvent | CB30: 0 | CC30: 0 | CD30: 1 | CE30: 0 | CF30: Manque de compétences numériques | CG30: 3 | CH30: 3 | CI30: 1 | CJ30: 4 | CK30: Autre | CL30: Une journée complète | CM30: Indifférent | CN30: Motiver les enseignants et former les encadreurs. | CO30: Manque de moyens et de suivi de proximité. | CP30: Motiver les enseignants et former les encadreurs.
A31: 30 | B31: 117-118-119-120 | C31: CEG 7 Porto-Novo | D31: Cotonou | E31: ATACORA | F31: Privé | G31: Féminin | H31: 50 ans et plus | I31: 11-20 ans | J31: AME | L31: Licence Pro | M31: Licence | N31: Sciences Humaines | P31: Non | Q31: 3 à 5 jours | R31: Oui | S31: 4 | T31: 0 | U31: 1 | V31: 0 | W31: 0 | X31: Ordinateur/tablette | Z31: 5 | AA31: 3 | AB31: 3 | AC31: 3 | AD31: 3 | AE31: 5 | AF31: 4 | AH31: 0 | AI31: 0 | AJ31: 1 | AK31: 0 | AL31: 0 | AM31: 0 | AN31: Établissement | AO31: 4 | AP31: 5 | AQ31: 4 | AS31: 3 | AT31: 1 | AU31: 3 | AV31: 0 | AW31: 1 | AX31: 1 | AY31: 0 | AZ31: 0 | BA31: Entretien individuel avec un encadreur | Mentorat/tutorat par un pair | BB31: 3 à 5 fois | BC31: 1 | BD31: 3 | BE31: 1 | BF31: 2 | BG31: 4 | BH31: 3 | BI31: 5 | BJ31: 3 | BK31: 5 | BL31: 4 | BM31: 3 | BN31: 3 | BO31: 5 | BP31: 4 | BQ31: 5 | BR31: 1 | BT31: 3 | BU31: 3 | BV31: 4 | BW31: 2 | BX31: 5 | BY31: 3 | BZ31: 2 | CA31: Souvent | CB31: 0 | CC31: 0 | CD31: 1 | CE31: 1 | CF31: Manque de compétences numériques | Pas d'obstacle majeur | CG31: 4 | CH31: 4 | CI31: 1 | CJ31: 5 | CK31: Mixte (présentiel + à distance) | CL31: Formation longue (plusieurs semaines continues) | CM31: Oui, absolument | CO31: Manque de moyens et de suivi de proximité. | CQ31: Manque de moyens et de suivi de proximité. | CR31: oui
A32: 31 | B32: 121-122-123-124 | C32: CEG 2 Lokossa | D32: Abomey | E32: OUEME | F32: Privé | G32: Féminin | H32: 40-49 ans | I32: plus de 20 ans | J32: FE | L32: CAPES | M32: BAC | N32: Lettres | P32: Oui | Q32: 6 à 10 jours | R32: Oui | S32: 1 | T32: 0 | U32: 0 | V32: 0 | W32: 1 | X32: Aucun de ces équipements | AB32: 3 | AC32: 3 | AD32: 2 | AE32: 4 | AF32: 4 | AG32: 4 | AH32: 0 | AI32: 0 | AJ32: 0 | AK32: 0 | AL32: 0 | AM32: 1 | AN32: Autre | AO32: 3 | AP32: 3 | AQ32: 2 | AR32: 2 | AS32: 1 | AT32: 3 | AU32: 4 | AV32: 0 | AW32: 0 | AX32: 1 | AY32: 0 | AZ32: 1 | BA32: Mentorat/tutorat par un pair | Aucun accompagnement reçu | BB32: Jamais | BC32: 4 | BD32: 4 | BF32: 2 | BG32: 5 | BH32: 4 | BI32: 4 | BK32: 4 | BL32: 4 | BN32: 2 | BO32: 3 | BP32: 5 | BQ32: 4 | BR32: 4 | BS32: 3 | BT32: 1 | BU32: 3 | BV32: 3 | BW32: 2 | BX32: 3 | BY32: 3 | BZ32: 5 | CA32: Rarement | CB32: 0 | CC32: 1 | CD32: 0 | CE32: 0 | CF32: Matériel insuffisant | CG32: 3 | CH32: 1 | CI32: 4 | CJ32: 4 | CK32: Autre | CL32: Deux jours consécutifs | CM32: Oui, absolument | CO32: Manque de moyens et de suivi de proximité. | CQ32: Manque de moyens et de suivi de proximité. | CR32: oui
A33: 32 | B33: 125-126-127-128 | C33: CEG 6 Abomey | D33: Cotonou | E33: LITTORAL | F33: Public | G33: Masculin | H33: 50 ans et plus | I33: 11-20 ans | J33: AME | L33: Licence Pro | M33: Maîtrise | N33: Sciences et Technologies | P33: Non | Q33: 1 à 2 jours | R33: Oui | S33: 4 | T33: 1 | U33: 0 | V33: 0 | W33: 1 | X33: Aucun de ces équipements | Smartphone | Y33: 5 | Z33: 3 | AA33: 5 | AB33: 3 | AC33: 4 | AD33: 2 | AE33: 3 | AF33: 3 | AG33: 3 | AH33: 1 | AI33: 0 | AJ33: 0 | AK33: 0 | AL33: 1 | AM33: 0 | AN33: Ministère | Initiative personnelle | AO33: 4 | AP33: 3 | AQ33: 5 | AR33: 5 | AS33: 5 | AT33: 4 | AU33: 3 | AV33: 0 | AW33: 1 | AX33: 0 | AY33: 1 | AZ33: 0 | BA33: Réunion collective de suivi (conseil d'enseignement, animation pédagogique) | Entretien individuel avec un encadreur | BC33: 2 | BD33: 4 | BE33: 5 | BF33: 2 | BG33: 4 | BH33: 4 | BI33: 4 | BJ33: 2 | BK33: 1 | BL33: 4 | BM33: 2 | BN33: 4 | BO33: 4 | BP33: 5 | BQ33: 1 | BR33: 3 | BS33: 4 | BT33: 4 | BU33: 3 | BV33: 5 | BW33: 4 | BX33: 3 | BY33: 5 | BZ33: 4 | CA33: Souvent | CB33: 1 | CC33: 0 | CD33: 0 | CE33: 0 | CF33: Accès limité à Internet | CG33: 4 | CH33: 4 | CI33: 2 | CJ33: 2 | CK33: Présentiel pur | CL33: Une journée complète | CM33: Plutôt non | CN33: Manque de moyens et de suivi de proximité. | CO33: Manque de moyens et de suivi de proximité. | CQ33: Motiver les enseignants et former les encadreurs. | CR33: oui
A34: 33 | B34: 129-130-131-132 | C34: CEG 5 Cotonou | D34: Natitingou | E34: BORGOU | F34: Privé | G34: Féminin | H34: moins de 30 ans | I34: 5-10 ans | J34: AME | L34: Licence Pro | M34: Master | N34: Lettres | P34: Oui | Q34: 1 à 2 jours | R34: Non | S34: 5 | T34: 0 | U34: 0 | V34: 1 | W34: 0 | X34: Connexion Internet à domicile | Y34: 4 | Z34: 3 | AA34: 3 | AB34: 4 | AC34: 3 | AD34: 3 | AE34: 2 | AF34: 4 | AG34: 5 | AH34: 0 | AI34: 0 | AJ34: 0 | AK34: 1 | AL34: 1 | AM34: 0 | AN34: Initiative personnelle | ONG/Partenaires | AO34: 5 | AP34: 2 | AQ34: 5 | AR34: 3 | AS34: 3 | AT34: 3 | AU34: 4 | AV34: 0 | AW34: 0 | AX34: 0 | AY34: 1 | AZ34: 0 | BA34: Réunion collective de suivi (conseil d'enseignement, animation pédagogique) | BB34: 1 à 2 fois | BC34: 4 | BD34: 3 | BE34: 4 | BF34: 2 | BG34: 2 | BH34: 3 | BI34: 5 | BJ34: 5 | BK34: 1 | BL34: 3 | BM34: 1 | BN34: 5 | BO34: 5 | BP34: 3 | BQ34: 4 | BR34: 4 | BS34: 1 | BT34: 2 | BU34: 4 | BV34: 5 | BW34: 5 | BX34: 4 | BY34: 4 | BZ34: 2 | CA34: Parfois | CB34: 0 | CC34: 1 | CD34: 1 | CE34: 0 | CF34: Matériel insuffisant | Manque de compétences numériques | CG34: 2 | CH34: 5 | CI34: 1 | CJ34: 1 | CK34: Autre | CL34: Formation longue (plusieurs semaines continues) | CM34: Indifférent | CN34: Motiver les enseignants et former les encadreurs. | CO34: Manque de moyens et de suivi de proximité. | CQ34: Motiver les enseignants et former les encadreurs. | CR34: oui
A35: 34 | B35: 133-134-135-136 | C35: CEG 5 Porto-Novo | D35: Natitingou | E35: MONO | F35: Public | G35: Féminin | H35: 30-39 ans | I35: plus de 20 ans | J35: ACDPE | L35: Master Pro | M35: Master | N35: Sciences et Technologies | P35: Oui | Q35: 3 à 5 jours | R35: Non | S35: 3 | T35: 1 | U35: 0 | V35: 1 | W35: 0 | X35: Connexion Internet à domicile | Smartphone | AB35: 2 | AC35: 1 | AD35: 5 | AE35: 3 | AF35: 5 | AG35: 4 | AH35: 0 | AI35: 0 | AJ35: 1 | AK35: 0 | AL35: 0 | AM35: 0 | AN35: Établissement | AO35: 3 | AP35: 3 | AQ35: 5 | AR35: 3 | AS35: 2 | AT35: 5 | AU35: 3 | AV35: 0 | AW35: 0 | AX35: 0 | AY35: 1 | AZ35: 0 | BA35: Réunion collective de suivi (conseil d'enseignement, animation pédagogique) | BB35: Plus de 5 fois | BC35: 4 | BD35: 2 | BE35: 3 | BF35: 2 | BG35: 3 | BH35: 2 | BI35: 2 | BJ35: 3 | BK35: 4 | BL35: 2 | BM35: 3 | BN35: 4 | BO35: 1 | BP35: 4 | BQ35: 4 | BR35: 5 | BT35: 3 | BU35: 4 | BV35: 5 | BW35: 5 | BX35: 2 | BY35: 2 | BZ35: 4 | CA35: Parfois | CB35: 1 | CC35: 0 | CD35: 0 | CE35: 0 | CF35: Accès limité à Internet | CG35: 2 | CH35: 5 | CI35: 5 | CJ35: 2 | CK35: Présentiel pur | CL35: Une journée complète | CM35: Non, pas nécessaire | CP35: Manque de moyens et de suivi de proximité. | CQ35: Motiver les enseignants et former les encadreurs. | CR35: oui
A36: 35 | B36: 137-138-139-140 | C36: CEG 1 Porto-Novo | D36: Lokossa | E36: OUEME | F36: Privé | G36: Masculin | H36: moins de 30 ans | I36: 11-20 ans | J36: AME | L36: CAPES | M36: Licence | N36: Sciences Humaines | P36: Oui | Q36: 1 à 2 jours | R36: Non | S36: Sans objet | T36: 0 | U36: 1 | V36: 0 | W36: 0 | X36: Ordinateur/tablette | Y36: 3 | Z36: 3 | AA36: 3 | AB36: 3 | AC36: 3 | AD36: 3 | AE36: 3 | AF36: 4 | AG36: 3 | AH36: 0 | AI36: 0 | AJ36: 0 | AK36: 1 | AL36: 0 | AM36: 0 | AN36: ONG/Partenaires | AO36: 1 | AP36: 3 | AQ36: 5 | AR36: 4 | AS36: 1 | AT36: 4 | AU36: 4 | AV36: 1 | AW36: 0 | AX36: 0 | AY36: 0 | AZ36: 1 | BA36: Visite de classe en situation | Aucun accompagnement reçu | BB36: Jamais | BC36: 4 | BD36: 3 | BE36: 3 | BF36: 1 | BG36: 3 | BH36: 4 | BI36: 5 | BJ36: 3 | BK36: 3 | BL36: 2 | BM36: 2 | BO36: 2 | BP36: 5 | BQ36: 1 | BR36: 4 | BS36: 3 | BT36: 4 | BU36: 4 | BV36: 3 | BW36: 2 | BX36: 5 | BY36: 4 | BZ36: 4 | CA36: Souvent | CB36: 0 | CC36: 0 | CD36: 1 | CE36: 0 | CF36: Manque de compétences numériques | CG36: 4 | CH36: 2 | CI36: 1 | CJ36: 2 | CK36: Autre | CL36: Modules répartis sur plusieurs semaines | CM36: Plutôt non | CN36: Motiver les enseignants et former les encadreurs. | CO36: Motiver les enseignants et former les encadreurs. | CP36: Manque de moyens et de suivi de proximité. | CR36: oui
A37: 36 | B37: 141-142-143-144 | C37: CEG 2 Cotonou | D37: Abomey | E37: ZOU | F37: Privé | G37: Masculin | H37: moins de 30 ans | I37: 5-10 ans | J37: ACDPE | L37: CAPES | M37: Maîtrise | N37: Autre | P37: Non | Q37: 6 à 10 jours | R37: Oui | S37: 4 | T37: 1 | U37: 1 | V37: 0 | W37: 0 | X37: Ordinateur/tablette | Smartphone | AB37: 2 | AC37: 2 | AD37: 4 | AE37: 4 | AF37: 3 | AG37: 3 | AH37: 0 | AI37: 0 | AJ37: 1 | AK37: 0 | AL37: 0 | AM37: 0 | AN37: Établissement | AO37: 2 | AP37: 5 | AQ37: 2 | AR37: 1 | AS37: 4 | AT37: 5 | AU37: 3 | AV37: 0 | AW37: 1 | AX37: 0 | AY37: 1 | AZ37: 0 | BA37: Réunion collective de suivi (conseil d'enseignement, animation pédagogique) | Entretien individuel avec un encadreur | BB37: 1 à 2 fois | BC37: 5 | BD37: 5 | BF37: 5 | BG37: 5 | BH37: 4 | BI37: 3 | BJ37: 4 | BK37: 5 | BL37: 5 | BM37: 5 | BN37: 5 | BO37: 2 | BP37: 5 | BQ37: 4 | BR37: 5 | BS37: 4 | BT37: 4 | BU37: 2 | BV37: 4 | BW37: 2 | BX37: 3 | BY37: 4 | BZ37: 2 | CA37: Rarement | CB37: 1 | CC37: 0 | CD37: 0 | CE37: 1 | CF37: Pas d'obstacle majeur | Accès limité à Internet | CG37: 3 | CH37: 3 | CI37: 4 | CJ37: 3 | CK37: Autre | CL37: Formation longue (plusieurs semaines continues) | CM37: Oui, absolument | CN37: Motiver les enseignants et former les encadreurs. | CO37: Motiver les enseignants et former les encadreurs. | CP37: Manque de moyens et de suivi de proximité. | CR37: oui
A38: 37 | B38: 145-146-147-148 | C38: CEG 1 Natitingou | D38: Parakou | E38: LITTORAL | F38: Public | G38: Féminin | H38: 50 ans et plus | I38: plus de 20 ans | J38: AME | L38: Licence Pro | M38: Maîtrise | N38: Lettres | P38: Non | Q38: Plus de 10 jours | R38: Oui | S38: 3 | T38: 1 | U38: 0 | V38: 0 | W38: 0 | X38: Smartphone | Y38: 2 | Z38: 3 | AA38: 4 | AB38: 4 | AC38: 5 | AD38: 2 | AE38: 2 | AF38: 2 | AG38: 1 | AH38: 1 | AI38: 0 | AJ38: 1 | AK38: 0 | AL38: 0 | AM38: 0 | AN38: Ministère | Établissement | AO38: 4 | AP38: 4 | AQ38: 3 | AR38: 1 | AS38: 5 | AT38: 5 | AU38: 4 | AV38: 0 | AW38: 0 | AX38: 0 | AY38: 1 | AZ38: 0 | BA38: Réunion collective de suivi (conseil d'enseignement, animation pédagogique) | BB38: 1 à 2 fois | BC38: 5 | BD38: 3 | BE38: 4 | BF38: 3 | BG38: 4 | BH38: 5 | BI38: 5 | BK38: 2 | BL38: 5 | BM38: 5 | BN38: 3 | BO38: 2 | BP38: 5 | BQ38: 4 | BR38: 1 | BS38: 3 | BT38: 5 | BU38: 3 | BV38: 4 | BW38: 4 | BX38: 4 | BY38: 4 | BZ38: 3 | CA38: Souvent | CB38: 0 | CC38: 0 | CD38: 1 | CE38: 1 | CF38: Pas d'obstacle majeur | Manque de compétences numériques | CG38: 4 | CH38: 5 | CI38: 4 | CJ38: 4 | CK38: Mixte (présentiel + à distance) | CL38: Deux jours consécutifs | CM38: Oui, absolument | CO38: Motiver les enseignants et former les encadreurs. | CP38: Motiver les enseignants et former les encadreurs. | CR38: oui
A39: 38 | B39: 149-150-151-152 | C39: CEG 6 Natitingou | D39: Lokossa | E39: MONO | F39: Public | G39: Masculin | H39: moins de 30 ans | I39: plus de 20 ans | J39: AME | L39: Licence Pro | M39: Master | N39: Lettres | P39: Non | R39: Oui | S39: 1 | T39: 0 | U39: 1 | V39: 1 | W39: 0 | X39: Connexion Internet à domicile | Ordinateur/tablette | Y39: 1 | Z39: 2 | AA39: 2 | AB39: 3 | AC39: 3 | AD39: 5 | AE39: 4 | AF39: 1 | AG39: 2 | AH39: 0 | AI39: 0 | AJ39: 1 | AK39: 1 | AL39: 0 | AM39: 0 | AN39: Établissement | ONG/Partenaires | AO39: 4 | AP39: 1 | AQ39: 5 | AR39: 4 | AS39: 4 | AT39: 3 | AU39: 4 | AV39: 0 | AW39: 0 | AX39: 0 | AY39: 1 | AZ39: 1 | BA39: Réunion collective de suivi (conseil d'enseignement, animation pédagogique) | Aucun accompagnement reçu | BB39: Plus de 5 fois | BC39: 1 | BD39: 2 | BE39: 4 | BF39: 4 | BG39: 3 | BH39: 3 | BI39: 3 | BJ39: 5 | BK39: 3 | BL39: 5 | BM39: 4 | BN39: 2 | BO39: 5 | BP39: 2 | BQ39: 2 | BR39: 3 | BT39: 3 | BU39: 5 | BV39: 1 | BW39: 3 | BX39: 3 | BY39: 4 | BZ39: 3 | CA39: Très souvent | CB39: 1 | CC39: 0 | CD39: 0 | CE39: 1 | CF39: Pas d'obstacle majeur | Accès limité à Internet | CG39: 5 | CH39: 3 | CJ39: 4 | CK39: Autre | CL39: Formation longue (plusieurs semaines continues) | CM39: Non, pas nécessaire | CP39: Manque de moyens et de suivi de proximité. | CQ39: Motiver les enseignants et former les encadreurs. | CR39: oui
A40: 39 | B40: 153-154-155-156 | C40: CEG 8 Natitingou | D40: Porto-Novo | E40: LITTORAL | F40: Public | G40: Masculin | H40: 30-39 ans | I40: plus de 20 ans | J40: FE | L40: BAPES | M40: BAC | N40: Sciences et Technologies | P40: Non | Q40: Plus de 10 jours | R40: Non | S40: 4 | T40: 1 | U40: 0 | V40: 0 | W40: 1 | X40: Aucun de ces équipements | Smartphone | AB40: 3 | AC40: 4 | AD40: 4 | AE40: 2 | AF40: 2 | AG40: 4 | AH40: 0 | AI40: 0 | AJ40: 0 | AK40: 1 | AL40: 0 | AM40: 0 | AN40: ONG/Partenaires | AO40: 4 | AP40: 4 | AQ40: 2 | AR40: 1 | AS40: 3 | AT40: 4 | AU40: 4 | AV40: 0 | AW40: 1 | AX40: 0 | AY40: 0 | AZ40: 0 | BA40: Entretien individuel avec un encadreur | BB40: Jamais | BC40: 4 | BD40: 3 | BE40: 2 | BG40: 2 | BH40: 3 | BJ40: 3 | BK40: 3 | BL40: 2 | BM40: 2 | BN40: 3 | BO40: 3 | BP40: 5 | BQ40: 3 | BR40: 3 | BS40: 4 | BT40: 3 | BU40: 2 | BV40: 3 | BW40: 4 | BX40: 5 | BY40: 3 | BZ40: 1 | CA40: Jamais | CB40: 0 | CC40: 0 | CD40: 1 | CE40: 0 | CF40: Manque de compétences numériques | CG40: 3 | CH40: 3 | CI40: 2 | CJ40: 4 | CK40: Mixte (présentiel + à distance) | CL40: Formation longue (plusieurs semaines continues) | CM40: Non, pas nécessaire | CO40: Motiver les enseignants et former les encadreurs. | CP40: Manque de moyens et de suivi de proximité. | CQ40: Manque de moyens et de suivi de proximité.
...

Sheet Dictionnaire
A1: Code | B1: Libellé de la question / affirmation | C1: Section | D1: Page | E1: Type | F1: Modalités | G1: Item inversé
A2: etablissement | B2: Établissement | C2: I. Informations générales | D2: 1 | E2: texte
A3: ville | B3: Ville | C3: I. Informations générales | D3: 1 | E3: texte
A4: departement | B4: Département | C4: I. Informations générales | D4: 1 | E4: texte
A5: type_etablissement | B5: Type d'établissement | C5: I. Informations générales | D5: 1 | E5: choix unique | F5: Public / Privé
A6: sexe | B6: Sexe | C6: I. Informations générales | D6: 1 | E6: choix unique | F6: Masculin / Féminin
A7: age | B7: Âge | C7: I. Informations générales | D7: 1 | E7: choix unique | F7: moins de 30 ans / 30-39 ans / 40-49 ans / 50 ans et plus
A8: anciennete | B8: Ancienneté dans l'enseignement | C8: I. Informations générales | D8: 1 | E8: choix unique | F8: moins de 5 ans / 5-10 ans / 11-20 ans / plus de 20 ans
A9: statut | B9: Statut professionnel | C9: I. Informations générales | D9: 1 | E9: choix unique | F9: FE / ACDPE / AME / Autre
A10: statut_autre | B10: Statut professionnel — précision « Autre » | C10: I. Informations générales | D10: 1 | E10: texte
A11: diplome_pro | B11: Diplôme professionnel | C11: I. Informations générales | D11: 1 | E11: choix unique | F11: CAPES / BAPES / Licence Pro / Master Pro
A12: diplome_academique | B12: Diplôme académique | C12: I. Informations générales | D12: 1 | E12: choix unique | F12: BAC / Licence / Maîtrise / Master
A13: discipline | B13: Discipline enseignée (groupe) | C13: I. Informations générales | D13: 1 | E13: choix unique | F13: Lettres / Sciences et Technologies / Sciences Humaines / Autre
A14: discipline_autre | B14: Discipline — précision « Autre » | C14: I. Informations générales | D14: 1 | E14: texte
A15: formation_12mois | B15: Avez-vous participé à au moins une activité de formation continue au cours des 12 derniers mois ? | C15: I. Informations générales | D15: 1 | E15: choix unique | F15: Oui / Non
A16: nb_jours_formation | B16: Si oui, combien de jours de formation avez-vous suivis (cumulés) ? | C16: I. Informations générales | D16: 1 | E16: choix unique | F16: 1 à 2 jours / 3 à 5 jours / 6 à 10 jours / Plus de 10 jours
A17: formation_distance | B17: Avez-vous déjà suivi une formation à distance ou hybride, même partiellement ? | C17: I. Informations générales | D17: 1 | E17: choix unique | F17: Oui / Non
A18: satisfaction_distance | B18: Si oui, niveau de satisfaction globale vis-à-vis de cette expérience | C18: I. Informations générales | D18: 1 | E18: choix unique | F18: 1 / 2 / 3 / 4 / 5 / Sans objet
A19: equipements | B19: Quel(s) équipement(s) personnel(s) utilisez-vous ou pourriez-vous utiliser pour vous former ? | C19: I. Informations générales | D19: 1 | E19: choix multiple | F19: Smartphone / Ordinateur/tablette / Connexion Internet à domicile / Aucun de ces équipements
A20: ame_a | B20: Je me sens suffisamment accompagné(e) dans mon insertion professionnelle en tant qu'AME. | C20: I bis. Volet spécifique AME | D20: 2 | E20: échelle 1-5 | F20: 1=Pas du tout d'accord / 2=Peu d'accord / 3=Neutre / 4=D'accord / 5=Tout à fait d'accord
A21: ame_b | B21: Mon statut d'AME limite mon accès aux mêmes formations que les enseignants titulaires. | C21: I bis. Volet spécifique AME | D21: 2 | E21: échelle 1-5 | F21: 1=Pas du tout d'accord / 2=Peu d'accord / 3=Neutre / 4=D'accord / 5=Tout à fait d'accord | G21: oui
A22: ame_c | B22: Un accompagnement spécifique aux AME, au-delà des formations générales, serait utile à mon intégration professionnelle. | C22: I bis. Volet spécifique AME | D22: 2 | E22: échelle 1-5 | F22: 1=Pas du tout d'accord / 2=Peu d'accord / 3=Neutre / 4=D'accord / 5=Tout à fait d'accord
A23: q1 | B23: Je suis régulièrement informé à l'avance des opportunités de formation. | C23: II. Politique et organisation de la formation continue | D23: 2 | E23: échelle 1-5 | F23: 1=Pas du tout d'accord / 2=Peu d'accord / 3=Neutre / 4=D'accord / 5=Tout à fait d'accord
A24: q2 | B24: Les formations sont organisées de façon ponctuelle, sans continuité dans l'année. | C24: II. Politique et organisation de la formation continue | D24: 2 | E24: échelle 1-5 | F24: 1=Pas du tout d'accord / 2=Peu d'accord / 3=Neutre / 4=D'accord / 5=Tout à fait d'accord | G24: oui
A25: q3 | B25: Les thèmes de formation sont choisis sans me consulter (décision descendante). | C25: II. Politique et organisation de la formation continue | D25: 2 | E25: échelle 1-5 | F25: 1=Pas du tout d'accord / 2=Peu d'accord / 3=Neutre / 4=D'accord / 5=Tout à fait d'accord | G25: oui
A26: q4 | B26: Les Animations Pédagogiques de Zone (APZ) répondent à mes besoins réels. | C26: II. Politique et organisation de la formation continue | D26: 2 | E26: échelle 1-5 | F26: 1=Pas du tout d'accord / 2=Peu d'accord / 3=Neutre / 4=D'accord / 5=Tout à fait d'accord
A27: q5 | B27: Les Animations Pédagogiques d'Établissement (APE/APH) sont utiles pour ma pratique quotidienne. | C27: II. Politique et organisation de la formation continue | D27: 2 | E27: échelle 1-5 | F27: 1=Pas du tout d'accord / 2=Peu d'accord / 3=Neutre / 4=D'accord / 5=Tout à fait d'accord
A28: q6 | B28: Les formations dépendent trop de projets extérieurs (ONG, bailleurs, projets temporaires). | C28: II. Politique et organisation de la formation continue | D28: 2 | E28: échelle 1-5 | F28: 1=Pas du tout d'accord / 2=Peu d'accord / 3=Neutre / 4=D'accord / 5=Tout à fait d'accord | G28: oui
A29: q7 | B29: Qui initie généralement les formations que vous suivez ? | C29: II. Politique et organisation de la formation continue | D29: 2 | E29: choix multiple | F29: Ministère / Inspection / Établissement / ONG/Partenaires / Initiative personnelle / Autre
A30: q8 | B30: Les formations répondent à mes besoins réels rencontrés en classe. | C30: III. Pertinence, approche pédagogique et réflexivité | D30: 2 | E30: échelle 1-5 | F30: 1=Pas du tout d'accord / 2=Peu d'accord / 3=Neutre / 4=D'accord / 5=Tout à fait d'accord
A31: q9 | B31: Les contenus sont trop théoriques et éloignés de ma réalité de terrain. | C31: III. Pertinence, approche pédagogique et réflexivité | D31: 2 | E31: échelle 1-5 | F31: 1=Pas du tout d'accord / 2=Peu d'accord / 3=Neutre / 4=D'accord / 5=Tout à fait d'accord | G31: oui
A32: q10 | B32: Les formations sont adaptées à l'Approche Par Compétences (APC) attendue dans les programmes. | C32: III. Pertinence, approche pédagogique et réflexivité | D32: 2 | E32: échelle 1-5 | F32: 1=Pas du tout d'accord / 2=Peu d'accord / 3=Neutre / 4=D'accord / 5=Tout à fait d'accord
A33: q11 | B33: Les formateurs valorisent mon expérience professionnelle. | C33: III. Pertinence, approche pédagogique et réflexivité | D33: 2 | E33: échelle 1-5 | F33: 1=Pas du tout d'accord / 2=Peu d'accord / 3=Neutre / 4=D'accord / 5=Tout à fait d'accord
A34: q12 | B34: On utilise des méthodes actives (ateliers, études de cas, résolution de problèmes) pendant les formations. | C34: III. Pertinence, approche pédagogique et réflexivité | D34: 2 | E34: échelle 1-5 | F34: 1=Pas du tout d'accord / 2=Peu d'accord / 3=Neutre / 4=D'accord / 5=Tout à fait d'accord
A35: q13 | B35: Je repars avec des outils ou fiches pratiques immédiatement utilisables en classe. | C35: III. Pertinence, approche pédagogique et réflexivité | D35: 2 | E35: échelle 1-5 | F35: 1=Pas du tout d'accord / 2=Peu d'accord / 3=Neutre / 4=D'accord / 5=Tout à fait d'accord
